Workbook

Sheet FY 2024 2025
A1: AA Inc
A2: Fixed Assets
A3: FY 2024 2025
B5: Beg Balance | E5: End Balance
A6: Assets | B6: 45383 | C6: Additions | D6: Disposals | E6: 45747
A8: Office Equip 15010 | B8: =+'FY 2023 2024'!E8 -> 223153.15 | C8: =+'Office & Computer Equip'!F149 -> 6924.27 | E8: =SUM(B8:D8) -> 230077.42 | F8: TB
A9: Furniture & Fixtures 15020 | B9: =+'FY 2023 2024'!E9 -> 163707.1 | E9: =SUM(B9:D9) -> 163707.1 | F9: TB
A10: Vehicles | B10: =+'FY 2023 2024'!E10 -> 0 | E10: =SUM(B10:D10) -> 0
A11: Tooling Rental Equip | B11: =+'FY 2023 2024'!E11 -> 0 | E11: =SUM(B11:D11) -> 0 | F11: TB
A12: Plant Equip 15050 | B12: =+'FY 2023 2024'!E12 -> 2128559.6 | C12: ='Plant Equip'!F115 -> 313251.47 | D12: =-6080.33-1487.3-7064.99 -> -14632.62 | E12: =SUM(B12:D12) -> 2427178.4 | F12: TB
A13: Buildings | B13: =+'FY 2023 2024'!E13 -> 0 | E13: =SUM(B13:D13) -> 0
A14: Land | B14: =+'FY 2023 2024'!E14 -> 0 | E14: =SUM(B14:D14) -> 0
B15: =SUM(B8:B14) -> 2515419.8 | C15: =SUM(C8:C14) -> 320175.74 | D15: =SUM(D8:D14) -> -14632.62 | E15: =SUM(E8:E14) -> 2820962.9 | F15: Thomson Reuters
B17: Beg Balance | E17: End Balance
A18: Accum Depreciation | B18: =+B6 -> 45383 | C18: Additions | D18: Disposals | E18: =+E6 -> 45747
A20: Office Equip 15019 | B20: =+'FY 2023 2024'!E20 -> -166839 | C20: =-1603.32-991.63-1522.69-991.64-1554.58-991.64-1554.59-991.65-1553.36-991.61-1301.43-991.65-1238-980.26-1154.59-995.7-1154.62-995.73-1154.62-995.73-1154.61-995.7-1154.6-698.78 -> -27712.73 | E20: =SUM(B20:D20) -> -194551.73 | F20: TB
A21: Furniture & Fixtures 15029 | B21: =+'FY 2023 2024'!E21 -> -146811.74 | C21: =-692.84-625.81-625.86-597.61-597.63-597.6-597.6-597.62-597.62-597.63-597.6-597.66 -> -7323.08 | E21: =SUM(B21:D21) -> -154134.82 | F21: TB
A22: Vehicles | B22: =+'FY 2023 2024'!E22 -> 0 | E22: =SUM(B22:D22) -> 0
A23: Tooling Rental Equip 15040 | B23: =+'FY 2023 2024'!E23 -> 0 | E23: =SUM(B23:D23) -> 0 | F23: TB
A24: Plant Equip 15059 | B24: =+'FY 2023 2024'!E24 -> -1961529.7 | C24: =-4473.95-4412.4-6376.73-6376.79-6376.79-6376.81-6376.78-6268.25-6268.35-6224.64-6213.08-6472.35 -> -72216.92 | D24: =6080.33+765.37+161.12 -> 7006.82 | E24: =SUM(B24:D24) -> -2026739.8 | F24: TB
A25: Buildings 15069 | B25: =+'FY 2023 2024'!E25 -> 0 | E25: =SUM(B25:D25) -> 0
B26: =SUM(B20:B25) -> -2275180.4 | C26: =SUM(C20:C25) -> -107252.73 | D26: =SUM(D20:D25) -> 7006.82 | E26: =SUM(E20:E25) -> -2375426.3 | F26: TB
B28: =+B15+B26 -> 240239.41 | C28: =+C15+C26 -> 212923.01 | D28: =+D15+D26 -> -7625.8 | E28: =+E15+E26 -> 445536.62 | F28: Thomson Reuters
A30: LH Improvements | B30: =+'FY 2023 2024'!E30 -> 41752.9 | E30: =SUM(B30:D30) -> 41752.9 | F30: TB
A31: Amort LH Improvement 15089-00 | B31: =+'FY 2023 2024'!E31 -> -10573.39 | C31: =-179.21-179.21-179.21-179.21-179.21-179.21-179.21-179.21-179.21-179.21-179.21-179.21 -> -2150.52 | D31: 0 | E31: =SUM(B31:D31) -> -12723.91 | F31: TB | G31: 20 year; SL | H31: =(43009.36/20)/12 -> 179.20567 | I31: 76220-09
A33: Fixed Assets Net | B33: =+B15+B30+B26+B31 -> 271418.92 | C33: =+C15+C30+C26+C31 -> 210772.49 | D33: =+D15+D30+D26+D31 -> -7625.8 | E33: =+E15+E30+E26+E31 -> 474565.61 | F33: TB
B34: PY
A38: PY = ok to FA report
A39: TB = ok to TB

Sheet Office & Computer Equip
A1: ='FY 2024 2025'!$A$1 -> AA Inc
A2: Office Equipment
A3: 15010-00
A6: Date | B6: KLA Asset # | C6: Vendor | D6: Item | E6: Serial Number | F6: Amount | G6: Dept | H6: Useful Life
A8: 41757 | C8: Costco | D8: Dell I3847 | F8: 670.79 | G8: 08BG | H8: 3
A9: 41758 | C9: Micro Source | D9: Latitude E6540 | E9: 4DT1WZ1 | F9: 1837.14 | G9: 04SG | H9: 3
A10: 41761 | C10: Micro Source | D10: Latitude E6540 | E10: 1VJ3WZ1 | F10: 1837.14 | G10: 07MG | H10: 3
A11: 41771 | C11: Sam's Club | D11: Dell 24 | F11: 740.94 | G11: 08MG | H11: 3
A12: 41800 | C12: Micro Source | D12: Latitude E6540 | E12: HF4CXZ1 | F12: 1571.51 | G12: 07BG | H12: 3
A13: 41803 | C13: Micro Source | D13: Latitude E6540 | E13: FG9N12961396016 | F13: 1653.18 | G13: 09 | H13: 3
A14: 41803 | C14: Micro Source | D14: Latitude E7240 | E14: 6XP2YY1 | F14: 1869.77 | G14: 09 | H14: 3
A15: 41813 | C15: Micro Source | D15: Latitude E6540 | E15: 173PD12 | F15: 1528.53 | G15: 07SG | H15: 3
A16: 41813 | C16: Micro Source | D16: Latitude E6540 | E16: PM0CXZ1 | F16: 1528.53 | G16: 07SG | H16: 3
A17: 41813 | C17: Micro Source | D17: Latitude E6540 | E17: 8J7TP02 | F17: 764.77 | G17: 09 | H17: 3
A18: 41828 | C18: Micro Source | D18: Latitude E6540 | E18: 7R4CXZ1 | F18: 1538.65 | G18: 09 | H18: 3
A19: 41878 | C19: KLD | D19: Cisco Router | F19: 2222.15 | G19: 09 | H19: 3
A20: 41855 | C20: Micro Source | D20: Project 2013 | F20: 566.04 | G20: 09 | H20: 3
A21: 41911 | C21: Micro Source | D21: Latitude E6540 | E21: 8Q5WJ12 | F21: 1673.9 | G21: 07SG | H21: 3
A22: 41912 | C22: Micro Source | D22: Latitude E6540 | E22: 9Z72K12 | F22: 1793.68 | G22: 05BG | H22: 3
A23: 41912 | C23: Fisher/Unitech | D23: Solid Works CAD Software | F23: 4250.6 | G23: 09 | H23: 3
A24: 41977 | C24: Micro Source | D24: Latitude E6540 | E24: 81FRJ12 | F24: 1744.92 | G24: 07BG | H24: 3
A25: 41988 | C25: Micro Source | D25: Precision M4800 BTX Base | E25: BNTWP12 | F25: 1925.12 | G25: 05BG | H25: 3
A26: 41996 | C26: Micro Source | D26: Insprion 3000 | E26: V226WLBMD | F26: 743.28 | G26: 09 | H26: 3
A27: 42005 | C27: Casualty | D27: Asset #185 Chris Kuhn | E27: 3KB8XY1 | F27: -1740.68 | G27: exclude from cash flow statement
A28: 42020 | C28: Micro Source | D28: Return E7240 in June | E28: 6XP2YY1 | F28: -1869.76
A29: 42025 | C29: Micro Source | D29: Latitude E6540 | E29: CNVXK12 | F29: 1563.28 | G29: 07SG | H29: 3
A30: 42025 | C30: Micro Source | D30: Latitude E6540 | E30: CFVXK12 | F30: 1563.28 | G30: 06 | H30: 3
A31: 42053 | C31: Micro Source | D31: OptiPlx 3020 MT | E31: 8P6GR22 | F31: 734.78 | G31: 07BG | H31: 3
F32: =SUM(F8:F31) -> 30711.54
A34: 42151 | C34: KLD | D34: Cisco Router - credit memo | F34: -1612.41 | G34: 09 | H34: 3
A35: 42151 | C35: KLD | D35: Cisco Router - JE | F35: -609.74 | G35: exclude from cash flow statement
A36: 42217 | C36: KLD | D36: Fiber Optic Cable | F36: 472.89 | G36: 09 | H36: 3
A37: 42217 | C37: KLD | D37: Network Switches | F37: 6181.2 | G37: 09 | H37: 3
A38: 42247 | C38: Various | D38: FA clean up | F38: -13698.94
A39: 42277 | C39: Micro Source | D39: Gilpatrick Computer | F39: 1565.78 | G39: 06 | H39: 3
A40: 42277 | D40: FA disposal | F40: -2822.43
A41: 42279 | C41: Micro Source | D41: Neagu Computer | F41: 1691.41 | G41: 06 | H41: 3
A42: 42331 | C42: Micro Source | D42: Quesada | F42: 1411.08 | G42: 04BG | H42: 3
A43: 42396 | C43: Cisco | D43: Phone system | F43: 28867.53 | G43: 09 | H43: 3
A44: 42439 | C44: Amazon | D44: HP DesignJet T120 | F44: 1022.86 | G44: 06 | H44: 5
...

Sheet F&F
A1: ='FY 2024 2025'!$A$1 -> AA Inc
A2: Furniture & Fixtures
A3: 15020-00
A6: Date | B6: Vendor | C6: Item | D6: Serial Number | E6: Amount | F6: Dept | G6: Useful Life
A8: 41817 | B8: Amazon | C8: 4 person workstation | E8: 3395 | F8: 07BG, 07MG, 08BG, 08MG | G8: 10
A9: 42090 | B9: Uline | C9: Reel Rack Starter | E9: 806.34 | F9: 08BG | G9: 10
E10: =SUM(E8:E9) -> 4201.34
A12: 42381 | B12: Payless Material Handling | C12: Teardrop Beams Wired Decking | E12: 2998.5 | F12: 08SG | G12: 10
A14: 42489 | B14: Crown Lift Trucks | C14: In Plant Office - 04MG | E14: 23285.71 | F14: 04MG | G14: 10
A15: 42551 | B15: Crown Lift Trucks | C15: In Plant Office - 08BG | E15: 23061.54 | F15: 08BG | G15: 10
A16: 42557 | B16: Ormsby Electric | C16: Elec Install for IPO 08BG | E16: 1860 | F16: 08BG | G16: 10
A17: 42613 | B17: The Floor Trader | C17: Flooring for IPO 08BG | E17: 1423.77 | F17: 08BG | G17: 10
A18: 42614 | B18: RJN | C18: Flooring for IPO 08BG | E18: 1086 | F18: 08BG | G18: 10
A19: 42740 | B19: Global | C19: 70" 9 Drawer Pit Box | E19: 3550.95 | F19: 04BG | G19: 10
E20: =SUM(E14:E19) -> 54267.97
A22: 42845 | B22: Perfection Indus Sales | C22: Conference Table w/ Chairs | E22: 914.5 | F22: 09 | G22: 7 | H22: b/c used
A23: 42845 | B23: Perfection Indus Sales | C23: Glass Display Cabinets | E23: 802.4 | F23: 09 | G23: 7 | H23: b/c used
A24: 42845 | B24: Perfection Indus Sales | C24: Black Granite Surface Plate | E24: 1327.5 | F24: 04MG | G24: 7 | H24: b/c used
A25: 42845 | B25: Perfection Indus Sales | C25: 5-Drawer Rolling Tool Cab | E25: 737.5 | F25: 06 | G25: 7 | H25: b/c used
A26: 42843 | B26: Perfection Indus Sales | C26: Assorted Plastic Bins | E26: 575 | F26: 08BG | G26: 7 | H26: b/c used
A27: 42843 | B27: Perfection Indus Sales | C27: (2) Maple Top Workbenches | E27: 1265 | F27: 06 | G27: 7 | H27: b/c used
A28: 42867 | B28: Stor-Loc | C28: Cabinet 59Hx461/2Wx273/4D | E28: 2556.75 | F28: 02 | G28: 10
A29: 42886 | B29: RCL | C29: RCL FROM COMPUTER | E29: 7236.36
A30: 42906 | B30: Walter USA | C30: (20) office cubicles | E30: 10000 | F30: 09 | G30: 10
E31: =SUM(E22:E30) -> 25415.01
A33: 43301 | B33: Amazon | C33: 85 Inch Sony HS Smart LED TV | E33: 4277.86 | F33: 04SG | G33: 7
A34: 43348 | B34: Stor-Loc | C34: Shallow Depth Cabinet | E34: 759.04 | F34: 02 | G34: 7
E35: =SUM(E33:E34) -> 5036.9

Sheet Plant Equip
A1: ='FY 2024 2025'!$A$1 -> AA Inc
A2: Plant Equipment
A3: 15050-00
A6: Date | B6: KLA Asset # | C6: Vendor | D6: Item | E6: Serial Number | F6: Amount | G6: Dept | H6: Useful Life
A8: 41772 | C8: SAFETY KLEEN | D8: Washer model 81.8 | E8: 10030566 | F8: 751.53 | G8: 08SG | H8: 10
A9: 41803 | C9: KLD | D9: Lead Master Type 100 - P-testers | F9: 15032 | G9: 07MG | H9: 10
A10: 41862 | C10: Brecoflex | D10: Tension Meter Device | F10: 622.5 | G10: 06 | H10: 7
A11: 41939 | C11: Laser Marking | D11: Laser Marking Equipment | F11: 12128 | G11: 02 | H11: 10
A12: 41944 | C12: Fed Ex | D12: Freight for Laser Marking | F12: 892.85 | G12: 02 | H12: 10
A13: 42005 | C13: Ann Arbor Welding | D13: Welder | F13: 5230.49 | G13: 06 | H13: 10
A14: 42024 | C14: American Hofmann | D14: Model MI-2100 SN 20152003 | F14: 8900 | G14: 06 | H14: 10
A15: 42027 | C15: McMaster-Carr | D15: Parallel Straightedge, 48" long | F15: 963.83 | G15: 08SG | H15: 7
A16: 42034 | C16: Ann Arbor Welding | D16: Install Welder | F16: 1399.74 | G16: 06 | H16: 10
A17: 42045 | C17: KLD | D17: Viper 500 K | F17: 721847.87 | G17: 04SG | H17: 10
A18: 42059 | C18: Ormsby Electric | D18: Intall receptale for Welder | F18: 957.81 | G18: 06 | H18: 10
A19: 42064 | C19: KLD | D19: Viper 500 K Interest | F19: -27347.87 | G19: 04SG | H19: 10
F20: =SUM(F8:F19) -> 741378.75
A22: 42125 | C22: KL | D22: Guage | F22: 34459 | G22: 08BG | H22: 7 | I22: per verbal with Alex Duerr
A23: 42153 | C23: Ingersoll Rand | D23: Compressor | F23: 6850 | G23: 02 | H23: 10
A24: 42153 | C24: Ingersoll Rand | D24: Oil Water Separator | F24: 1568.5 | G24: 02 | H24: 10
A25: 42163 | C25: Ormsby Electric | D25: Compressor - electric hook up | F25: 1380 | G25: 02 | H25: 10
A26: 42165 | C26: Ingersoll Rand | D26: Compressor - labor to install | F26: 550 | G26: 02 | H26: 10
A27: 42174 | C27: Ingersoll Rand | D27: Compressor - intall | F27: 1715 | G27: 02 | H27: 10
A28: 42184 | C28: Ann Arbor Welding | D28: Bandsaw 115 V | F28: 1766.88 | G28: 06 | H28: 10
A29: 42185 | C29: Methods Machine Tools | D29: Fanuc C600iA-12 - EDM | F29: 14615 | G29: 02 | H29: 10
A30: 42186 | C30: KLD | D30: Control device complete C20/C28/C27 | F30: 8376.87 | G30: 08BG | H30: 7
A31: 42208 | C31: Floyd's Rigging | D31: Unload EDM | F31: 2762 | G31: 02 | H31: 10
A32: 42212 | C32: Grainger | D32: Charging/Gauging Kit | F32: 539 | G32: 07BG | H32: 7
A33: 42214 | C33: Methods Machine Tools | D33: Fanuc C600iA-12 - EDM | F33: 131535 | G33: 02 | H33: 10
A34: 42217 | C34: Ann Arbor Welding | D34: Saw Horse - Heavy Duty | F34: 1673.6 | G34: 06 | H34: 10
... A36: 42300 | C36: KLD | D36: Guages for calibrating machines | F36: 6150 | G36: 07MG | H36: 7
F37: =SUM(F22:F36) -> 215497.85
A39: 42843 | C39: Perfection Indus Sales | D39: Cap Pallet Jack | F39: 4140 | G39: 06 | H39: 7 | I39: b/c used
A40: 42843 | C40: Perfection Indus Sales | D40: Pallet Truck Scale | F40: 1035 | G40: 08BG | H40: 7 | I40: b/c used
A41: 42860 | C41: KLD | D41: Measuring Disc for Viper | F41: 5225.88 | G41: 07SG | H41: 10
A42: 42867 | C42: Safety Kleen | D42: Wash Station | F42: =4239.99 -> 4239.99 | G42: 02 | H42: 10
A43: 42867 | C43: CMC | D43: Tool for locking ZARF beraing on HF8000 | F43: 845 | G43: 07SG | H43: 10
A44: 43004 | C44: Starrett | D44: Single Parellel 6FAA | F44: 2284 | G44: 07MG | H44: 10
A45: 43004 | C45: Starrett | D45: Single Parellel 6FAA | F45: 2330 | G45: 07SG | H45: 10
A46: 43010 | C46: Advanced Industries | D46: Wendeplatte Links | F46: 875 | G46: 06 | H46: 10
...

Sheet LH Improvement
A1: ='FY 2024 2025'!$A$1 -> AA Inc
A2: LH Improvement
A3: 15080-00
A5: Date | B5: Vendor | C5: Item | D5: Serial Number | E5: Amount | F5: Dept | G5: Useful Life
A7: 43616 | B7: HIDC | C7: Shop bathrooms - remodel | E7: 43009.36 | F7: 09 | G7: 20
A8: 43637 | B8: HIDC | C8: Shop bathrooms - remodel addt'l inv | E8: -1256.46 | F8: 09 | G8: 20
E9: =SUM(E7:E8) -> 41752.9
A11: Budget | C11: Office space | E11: 200000 | F11: 09 | G11: 20 | H11: =E11/G11 -> 10000 | I11: =H11/12 -> 833.33333

Sheet Disposals FY 2024 2025
A1: ='FY 2024 2025'!$A$1 -> AA Inc
A2: FA Disposals
A3: FY 2024 2025
A5: 1. | B5: Asset #51 - April 2024 - disposed of B27 Grinding Wheel E0423
B7: JE # 16133
B8: A/D | C8: 6080.33 | E8: 15059-00
B9: Asset | D9: =+C8 -> 6080.33 | E9: 15050-00
A12: 2. | B12: Asset #516 - March 2025 - was on loan and now sold to AAM - invoiced AAM 8,414.00 | J12: Proceeds
B14: JE #
B15: A/D | C15: 765.37 | E15: 15059-00
B16: Loss | C16: =D17-C15 -> 6299.62 | E16: 95500-05BG
B17: Asset | D17: 7064.99 | E17: 15050-00
A20: 3. | B20: Asset #517 - March 2025 - was on loan and now sold to AAM - invoiced AAM 1,562.00 | J20: Proceeds
B22: JE #
B23: A/D | C23: 161.12 | E23: 15059-00
B24: Loss | C24: =D25-C23 -> 1326.18 | E24: 95500-05BG | I24: =8414+1562 -> 9976 | J24: total proceeds
B25: Asset | D25: 1487.3 | E25: 15050-00 | I25: =C24+C16 -> 7625.8 | J25: loss recorded in acct 95500-08BG
I26: =I24-I25 -> 2350.2 | J26: gain to put on FIT payable wp

Sheet FY 2023 2024
A1: ='FY 2024 2025'!$A$1 -> AA Inc
A2: Fixed Assets
A3: FY 2023 2024
B5: Beg Balance | E5: End Balance
A6: Assets | B6: 45017 | C6: Additions | D6: Disposals | E6: 45382
A8: Office Equip 15010 | B8: =+'FY 2022 2023'!E8 -> 258268.24 | C8: =+'Office & Computer Equip'!F142 -> 27761.52 | D8: =-15948.18-743.28-27920.72-18264.43 -> -62876.61 | E8: =SUM(B8:D8) -> 223153.15 | F8: TB
A9: Furniture & Fixtures 15020 | B9: =+'FY 2022 2023'!E9 -> 167984.96 | D9: -4277.86 | E9: =SUM(B9:D9) -> 163707.1 | F9: TB
A10: Vehicles | B10: =+'FY 2022 2023'!E10 -> 0 | E10: =SUM(B10:D10) -> 0
A11: Tooling Rental Equip | B11: =+'FY 2022 2023'!E11 -> 0 | E11: =SUM(B11:D11) -> 0 | F11: TB
A12: Plant Equip 15050 | B12: =+'FY 2022 2023'!E12 -> 2247549.3 | C12: =+'Plant Equip'!F109 -> 35550.1 | D12: =-11006.47-2702.37-139204-1627 -> -154539.84 | E12: =SUM(B12:D12) -> 2128559.6 | F12: TB
A13: Buildings | B13: =+'FY 2022 2023'!E13 -> 0 | E13: =SUM(B13:D13) -> 0
A14: Land | B14: =+'FY 2022 2023'!E14 -> 0 | E14: =SUM(B14:D14) -> 0
B15: =SUM(B8:B14) -> 2673802.5 | C15: =SUM(C8:C14) -> 63311.62 | D15: =SUM(D8:D14) -> -221694.31 | E15: =SUM(E8:E14) -> 2515419.8 | F15: Thomson Reuters
B17: Beg Balance | E17: End Balance
A18: Accum Depreciation | B18: =+B6 -> 45017 | C18: Additions | D18: Disposals | E18: =+E6 -> 45382
A20: Office Equip 15019 | B20: =+'FY 2022 2023'!E20 -> -196576.99 | C20: =-1623.55-724.61-1673.36-724.61-1754.89-971.88-1754.98-971.9-1793.86-971.86-1793.93-971.89-1793.85-981.65-1741.84-981.58-1787.87-981.65-1766.7-981.65-30.78-1585.51-981.62-1536.46-981.63-4.09 -> -31868.2 | D20: =15948.18+743.28+27381.5+18264.43-731.2 -> 61606.19 | E20: =SUM(B20:D20) -> -166839 | F20: TB
A21: Furniture & Fixtures 15029 | B21: =+'FY 2022 2023'!E21 -> -141030.71 | C21: =-948.25-858.2-743.76-743.74-692.88-692.8-692.81-692.86-692.83-692.84-692.85-692.82 -> -8836.64 | D21: 3055.61 | E21: =SUM(B21:D21) -> -146811.74 | F21: TB
A22: Vehicles | B22: =+'FY 2022 2023'!E22 -> 0 | E22: =SUM(B22:D22) -> 0
A23: Tooling Rental Equip 15040 | B23: =+'FY 2022 2023'!E23 -> 0 | E23: =SUM(B23:D23) -> 0 | F23: TB
A24: Plant Equip 15059 | B24: =+'FY 2022 2023'!E24 -> -2060353.1 | C24: =-4410.42-4371.85-4454.41-5028.45-5020.76-4979.87+596.05+596.05+596.05-4383.78-4321.87-4321.84-4408.25-4408.33-4419.07 -> -52740.75 | D24: =8030.79+2702.37+139204+1627 -> 151564.16 | E24: =SUM(B24:D24) -> -1961529.7 | F24: TB
A25: Buildings 15069 | B25: =+'FY 2022 2023'!E25 -> 0 | E25: =SUM(B25:D25) -> 0
B26: =SUM(B20:B25) -> -2397960.8 | C26: =SUM(C20:C25) -> -93445.59 | D26: =SUM(D20:D25) -> 216225.96 | E26: =SUM(E20:E25) -> -2275180.4 | F26: TB
B28: =+B15+B26 -> 275841.73 | C28: =+C15+C26 -> -30133.97 | D28: =+D15+D26 -> -5468.35 | E28: =+E15+E26 -> 240239.41 | F28: Thomson Reuters
A30: LH Improvements | B30: =+'FY 2022 2023'!E30 -> 41752.9 | E30: =SUM(B30:D30) -> 41752.9 | F30: TB
A31: Amort LH Improvement 15089-00 | B31: =+'FY 2022 2023'!E31 -> -8422.87 | C31: =-179.21-179.21-179.21-179.21-179.21-179.21-179.21-179.21-179.21-179.21-179.21-179.21 -> -2150.52 | D31: 0 | E31: =SUM(B31:D31) -> -10573.39 | F31: TB | G31: 20 year; SL | H31: =(43009.36/20)/12 -> 179.20567 | I31: 76220-09
A33: Fixed Assets Net | B33: =+B15+B30+B26+B31 -> 309171.76 | C33: =+C15+C30+C26+C31 -> -32284.49 | D33: =+D15+D30+D26+D31 -> -5468.35 | E33: =+E15+E30+E26+E31 -> 271418.92 | F33: TB
B34: PY
A38: PY = ok to FA report
A39: TB = ok to TB

Sheet Disposals FY 2023 2024
A1: ='FY 2024 2025'!$A$1 -> AA Inc
A2: FA Disposals
A3: FY 2023 2024
A5: 1. | B5: Asset #104 - April 2023 - disposed of B27 Grinding Wheel E1049 (1 of 4); vendor damaged
B7: JE # 15032
B8: A/D | C8: 3182.67 | E8: 15059-00
B9: Asset | D9: =+C8 -> 3182.67 | E9: 15050-00
A12: 2. | B12: Asset #111 - April 2023 - disposed of B27 Grinding Wheel E1148 (1 of 6); vendor damaged
B14: JE # 15033
B15: A/D | C15: 3186.38 | E15: 15059-00
B16: Asset | D16: =+C15 -> 3186.38 | E16: 15050-00
A19: 3. | B19: Asset #421 - April 2023 - disposed of B27 Grinding Wheel E2012; vendor damaged
B21: JE # 15034
B22: A/D | C22: 830.87 | E22: 15059-00
B23: Loss | C23: =+D24-C22 -> 1487.84 | E23: 95500-02
B24: Asset | D24: 2318.71 | E24: 15050-00
A27: 4. | B27: Asset #423 - April 2023 - disposed of B27 Grinding Wheel E2016; vendor damaged
B29: JE # 15035
B30: A/D | C30: 830.87 | E30: 15059-00
B31: Loss | C31: =+D32-C30 -> 1487.84 | E31: 95500-02
B32: Asset | D32: 2318.71 | E32: 15050-00
A35: 5. | B35: Asset #115 June 2023 - disposed of SAP007 Xerox WorkCentre 7120 Front Office
B37: JE # 15189
B38: A/D | C38: 5565.38 | E38: 15019-00
B39: Asset | D39: =+C38 -> 5565.38 | E39: 15010-00
A42: 6. | B42: Asset #119 June 2023 - disposed of SAP008 Xerox WorkCentre 7120 Srv Office
B44: JE # 15190
B45: A/D | C45: 5788.3 | E45: 15019-00
B46: Asset | D46: =+C45 -> 5788.3 | E46: 15010-00
A49: 7. | B49: Asset #374 June 2023 - disposed of SAP013 XeroxColor WC 72259t2i Parts Office
B51: JE # 15191
B52: A/D | C52: 4594.5 | E52: 15019-00
B53: Asset | D53: =+C52 -> 4594.5 | E53: 15010-00
A56: 8. | B56: Asset #400 July 2023 - disposed Sony 85" LED TV
B58: JE # 15191
B59: A/D | C59: 3055.61 | E59: 15029-00
B60: Loss | C60: =D61-C59 -> 1222.25 | E60: 95500-04SG
B61: Asset | D61: 4277.86 | E61: 15020-00
A64: 9. | B64: Asset #508 Sept 2023 - should not have been a FA yet
B66: deleted asset in Sept 2023
...

Sheet FY 2022 2023
A1: ='FY 2024 2025'!$A$1 -> AA Inc
A2: Fixed Assets
A3: FY 2022 2023
B5: Beg Balance | E5: End Balance
A6: Assets | B6: 44652 | C6: Additions | D6: Disposals | E6: 45016
A8: Office Equip 15010 | B8: =+'FY 2021 2022'!E8 -> 222214.8 | C8: =+'Office & Computer Equip'!F128 -> 52624.06 | D8: =-778.62-15792 -> -16570.62 | E8: =SUM(B8:D8) -> 258268.24 | F8: TB
A9: Furniture & Fixtures 15020 | B9: =+'FY 2021 2022'!E9 -> 167984.96 | E9: =SUM(B9:D9) -> 167984.96 | F9: TB
A10: Vehicles | B10: =+'FY 2021 2022'!E10 -> 0 | E10: =SUM(B10:D10) -> 0
A11: Tooling Rental Equip | B11: =+'FY 2021 2022'!E11 -> 0 | E11: =SUM(B11:D11) -> 0 | F11: TB
A12: Plant Equip 15050 | B12: =+'FY 2021 2022'!E12 -> 2204015.3 | C12: =+'Plant Equip'!F95 -> 46236.34 | D12: -2702.37 | E12: =SUM(B12:D12) -> 2247549.3 | F12: TB
A13: Buildings | B13: =+'FY 2021 2022'!E13 -> 0 | E13: =SUM(B13:D13) -> 0
A14: Land | B14: =+'FY 2021 2022'!E14 -> 0 | E14: =SUM(B14:D14) -> 0
B15: =SUM(B8:B14) -> 2594215.1 | C15: =SUM(C8:C14) -> 98860.4 | D15: =SUM(D8:D14) -> -19272.99 | E15: =SUM(E8:E14) -> 2673802.5 | F15: Thomson Reuters
B17: Beg Balance | E17: End Balance
A18: Accum Depreciation | B18: =+B6 -> 44652 | C18: Additions | D18: Disposals | E18: =+E6 -> 45016
A20: Office Equip 15019 | B20: =+'FY 2021 2022'!E20 -> -187016.76 | C20: =-1159.25-517.96-1382.25-517.94-1470.05-821.71-1470.06-821.71-1574.64-821.71-1324.74-821.7-1324.7-821.71-1465.09-895.32-1415.72-895.32-1415.74-895.35-1443.98-705.13-1443.94-705.13 -> -26130.85 | D20: =778.62+15792 -> 16570.62 | E20: =SUM(B20:D20) -> -196576.99 | F20: TB
A21: Furniture & Fixtures 15029 | B21: =+'FY 2021 2022'!E21 -> -127739.87 | C21: =-1223.78-1223.73-1223.79-1223.72-1223.79-1172.28-1117.18-1043.71-994.1-948.25-948.26-948.25 -> -13290.84 | E21: =SUM(B21:D21) -> -141030.71 | F21: TB
A22: Vehicles | B22: =+'FY 2021 2022'!E22 -> 0 | E22: =SUM(B22:D22) -> 0
A23: Tooling Rental Equip 15040 | B23: =+'FY 2021 2022'!E23 -> 0 | E23: =SUM(B23:D23) -> 0 | F23: TB
A24: Plant Equip 15059 | B24: =+'FY 2021 2022'!E24 -> -2006237.8 | C24: =-5064.93-5064.96-5136.09-5036.36-4830-4773.08-4773.08-4526.41-4526.41-4376.09-4337.31-4372.9 -> -56817.62 | D24: 2702.37 | E24: =SUM(B24:D24) -> -2060353.1 | F24: TB
A25: Buildings 15069 | B25: =+'FY 2021 2022'!E25 -> 0 | E25: =SUM(B25:D25) -> 0
B26: =SUM(B20:B25) -> -2320994.4 | C26: =SUM(C20:C25) -> -96239.31 | D26: =SUM(D20:D25) -> 19272.99 | E26: =SUM(E20:E25) -> -2397960.8 | F26: TB
B28: =+B15+B26 -> 273220.64 | C28: =+C15+C26 -> 2621.09 | D28: =+D15+D26 -> 0 | E28: =+E15+E26 -> 275841.73 | F28: Thomson Reuters
A30: LH Improvements | B30: =+'FY 2021 2022'!E30 -> 41752.9 | E30: =SUM(B30:D30) -> 41752.9 | F30: TB
A31: Amort LH Improvement 15089-00 | B31: =+'FY 2021 2022'!E31 -> -6272.35 | C31: =-179.21-179.21-179.21-179.21-179.21-179.21-179.21-179.21-179.21-179.21-179.21-179.21 -> -2150.52 | D31: 0 | E31: =SUM(B31:D31) -> -8422.87 | F31: TB | G31: 20 year; SL | H31: =(43009.36/20)/12 -> 179.20567 | I31: 76220-09
A33: Fixed Assets Net | B33: =+B15+B30+B26+B31 -> 308701.19 | C33: =+C15+C30+C26+C31 -> 470.57 | D33: =+D15+D30+D26+D31 -> 0 | E33: =+E15+E30+E26+E31 -> 309171.76 | F33: TB
B34: PY
A38: PY = ok to FA report
A39: TB = ok to TB

Sheet Disposals FY 2022 2023
A1: ='FY 2024 2025'!$A$1 -> AA Inc
A2: FA Disposals
A3: FY 2022 2023
A5: 1. | B5: Asset #53 - April 2022 - disposed of B27 Grinding Wheel E0517
B7: JE # 13964
B8: A/D | C8: 2702.37 | E8: 15059-00
B9: Asset | D9: =+C8 -> 2702.37 | E9: 15050-00
A12: 2. | B12: Asset #126 - March 2023
B14: JE # 14836
B15: A/D | C15: 778.62 | E15: 15019-00
B16: Asset | D16: =+C15 -> 778.62 | E16: 15010-00
A19: 2. | B19: Asset #154 - March 2023 - JobBoss seats; replaced with Cloud Host
B21: JE # 14837
B22: A/D | C22: 15792 | E22: 15019-00
B23: Asset | D23: =+C22 -> 15792 | E23: 15010-00

Sheet FY 2021 2022
A1: ='FY 2024 2025'!$A$1 -> AA Inc
A2: Fixed Assets
A3: FY 2021 2022
B5: Beg Balance | E5: End Balance
A6: Assets | B6: 44287 | C6: Additions | D6: Disposals | E6: 44651
A8: Office Equip 15010 | B8: =+'FY 2020 2021'!E8 -> 277803.15 | C8: =+'Office & Computer Equip'!F107 -> 18921.26 | D8: =-1563.28-1837.14-734.78-14152.04-34459-21763.37 -> -74509.61 | E8: =SUM(B8:D8) -> 222214.8 | F8: TB
A9: Furniture & Fixtures 15020 | B9: =+'FY 2020 2021'!E9 -> 167984.96 | E9: =SUM(B9:D9) -> 167984.96 | F9: TB
A10: Vehicles | B10: =+'FY 2019 2020'!E10 -> 0 | E10: =SUM(B10:D10) -> 0
A11: Tooling Rental Equip | B11: =+'FY 2019 2020'!E11 -> 0 | E11: =SUM(B11:D11) -> 0 | F11: TB
A12: Plant Equip 15050 | B12: =+'FY 2020 2021'!E12 -> 2254981.9 | C12: =+'Plant Equip'!F83 -> 20548.56 | D12: =-69000-2515.13 -> -71515.13 | E12: =SUM(B12:D12) -> 2204015.3 | F12: TB
A13: Buildings | B13: =+'FY 2019 2020'!E13 -> 0 | E13: =SUM(B13:D13) -> 0
A14: Land | B14: =+'FY 2019 2020'!E14 -> 0 | E14: =SUM(B14:D14) -> 0
B15: =SUM(B8:B14) -> 2700770 | C15: =SUM(C8:C14) -> 39469.82 | D15: =SUM(D8:D14) -> -146024.74 | E15: =SUM(E8:E14) -> 2594215.1 | F15: Thomson Reuters
B17: Beg Balance | E17: End Balance
A18: Accum Depreciation | B18: =+B6 -> 44287 | C18: Additions | D18: Disposals | E18: =+E6 -> 44651
A20: Office Equip 15019 | B20: =+'FY 2020 2021'!E20 -> -245368.27 | C20: =-1246.84-621.82-1186.12-621.8-1186.06-621.82+6522.37-1157.86-621.8-1157.87-621.8-1409.81-621.81-1234.54-621.82-1234.6-621.8-1177.66-621.81-1177.61-594.53-1177.67-594.53-1133.49-594.53 -> -15337.63 | D20: =1563.28+1837.14+734.78+14152.04+33228.3+410.23+21763.37 -> 73689.14 | E20: =SUM(B20:D20) -> -187016.76 | F20: TB
A21: Furniture & Fixtures 15029 | B21: =+'FY 2020 2021'!E21 -> -106300.92 | C21: =-1254.41-1254.41-1254.4-6522.32-1254.39-1254.43-1254.37-1254.35-1232.29-1232.29-1223.76-1223.77-1223.76 -> -21438.95 | E21: =SUM(B21:D21) -> -127739.87 | F21: TB
A22: Vehicles | B22: =+'FY 2019 2020'!E25 -> 0 | E22: =SUM(B22:D22) -> 0
A23: Tooling Rental Equip 15040 | B23: =+'FY 2019 2020'!E26 -> 0 | E23: =SUM(B23:D23) -> 0 | F23: TB
A24: Plant Equip 15059 | B24: =+'FY 2020 2021'!E24 -> -1970622.5 | C24: =-11541.89-11561.9-11574.34-8.94+0.02-11603.81-11596.47-11596.44-11621.63-5305.51-5305.48-5353.03-5235.7-4825.37 -> -107130.49 | D24: =69000+2515.13 -> 71515.13 | E24: =SUM(B24:D24) -> -2006237.8 | F24: TB
A25: Buildings 15069 | B25: =+'FY 2019 2020'!E28 -> 0 | E25: =SUM(B25:D25) -> 0
B26: =SUM(B20:B25) -> -2322291.6 | C26: =SUM(C20:C25) -> -143907.07 | D26: =SUM(D20:D25) -> 145204.27 | E26: =SUM(E20:E25) -> -2320994.4 | F26: TB
B28: =+B15+B26 -> 378478.36 | C28: =+C15+C26 -> -104437.25 | D28: =+D15+D26 -> -820.47 | E28: =+E15+E26 -> 273220.64 | F28: Thomson Reuters
A30: LH Improvements | B30: =+'FY 2019 2020'!E17 -> 41752.9 | C30: 0 | E30: =SUM(B30:D30) -> 41752.9 | F30: TB
A31: Amort LH Improvement 15089-00 | B31: =+'FY 2020 2021'!E31 -> -4121.83 | C31: =-179.21-179.21-179.21-179.21-179.21-179.21-179.21-179.21-179.21-179.21-179.21-179.21 -> -2150.52 | D31: 0 | E31: =SUM(B31:D31) -> -6272.35 | F31: TB | G31: 20 year; SL | H31: =(43009.36/20)/12 -> 179.20567 | I31: 76220-09
A33: Fixed Assets Net | B33: =+B15+B30+B26+B31 -> 416109.43 | C33: =+C15+C30+C26+C31 -> -106587.77 | D33: =+D15+D30+D26+D31 -> -820.47 | E33: =+E15+E30+E26+E31 -> 308701.19 | F33: TB
B34: PY
A38: PY = ok to FA report
A39: TB = ok to TB

Sheet Disposal FY 2021 2022
A1: ='FY 2024 2025'!$A$1 -> AA Inc
A2: FA Disposals
A3: FY 2021 2022
A5: 1. | B5: Asset #327 - April 2021 - disposed of KLSU0059 Frey CFVXK12
B7: JE # 12896
B8: A/D | C8: 1563.28 | E8: 15019-00
B9: Asset | D9: =+C8 -> 1563.28 | E9: 15010-00
A12: 2. | B12: Asset #103 - May 2021 - BC10 scrapped
B14: JE # 12942
B15: A/D | C15: 69000 | E15: 15059-00
B16: Asset | D16: =+C15 -> 69000 | E16: 15050-00
A19: 3. | B19: Asset #195 - May 2021 - disposed of KLUS0031 Plank 1VJ3WZ1
B21: JE # 12965
B22: A/D | C22: 1837.14 | E22: 15019-00
B23: Asset | D23: =+C22 -> 1837.14 | E23: 15010-00
A27: 4. | B27: Asset #330 - May 2021 - disposed of KLUS0060 Millan 8P6GR22
B29: JE # 12990
B30: A/D | C30: 734.78 | E30: 15019-00
B31: Asset | D31: =+C30 -> 734.78 | E31: 15010-00
A34: 5. | B34: Asset #175 - Sept 2021 - disposed of Avaya phone system
B36: JE # 13274
B37: A/D | C37: 14152.04 | E37: 15019-00
B38: Asset | D38: =+C37 -> 14152.04 | E38: 15010-00
A41: 6. | B41: Asset #338 - Feb 2022 - Gauge (customer AAM lost)
B43: JE # 13767
B44: A/D | C44: 33228.3 | E44: 15019-00
B45: Loss | C45: =+D46-C44 -> 1230.7 | E45: 95500-08BG
B46: Asset | D46: 34459 | E46: 15010-00
A49: 7. | B49: Asset #338 - Feb 2022 - Gauge (customer AAM lost) - ADJ to gain/loss current month depr included Feb
B51: JE # 13786
B52: A/D | C52: 410.23 | E52: 15019-00
B53: Gain | D53: 410.23 | E53: 95500-08BG
A56: 8. | B56: Assets: | C56: 122 | D56: 186 | F56: Computer annual review resulted in 13 disposals from asset list
C57: 125 | D57: 188 | F57: Computer annual review resulted in 7 disposals not on asset list
C58: 150 | D58: 189
C59: 152 | D59: 194
C60: 163 | D60: 326
C61: 180 | D61: 358
C62: 183
B64: JE # 13844
...

Sheet FY 2020 2021
A1: ='FY 2024 2025'!$A$1 -> AA Inc
A2: Fixed Assets
A3: FY 2020 2021
B5: Beg Balance | E5: End Balance
A6: Assets | B6: 43922 | C6: Additions | D6: Disposals | E6: 44286
A8: Office Equip 15010 | B8: =+'FY 2019 2020'!E8 -> 294163.48 | C8: =+'Office & Computer Equip'!F96 -> 9422.58 | D8: =-'Disposal FY 2020 2021'!D19-'Disposal FY 2020 2021'!D26-'Disposal FY 2020 2021'!D33-'Disposal FY 2020 2021'!D40-'Disposal FY 2020 2021'!D64-'Disposal FY 2020 2021'!D77-'Disposal FY 2020 2021'!D106 -> -25782.91 | E8: =SUM(B8:D8) -> 277803.15 | F8: TB
A9: Furniture & Fixtures 15020 | B9: =+'FY 2019 2020'!E9 -> 167984.96 | E9: =SUM(B9:D9) -> 167984.96 | F9: TB
A10: Vehicles | B10: =+'FY 2019 2020'!E10 -> 0 | E10: =SUM(B10:D10) -> 0
A11: Tooling Rental Equip | B11: =+'FY 2019 2020'!E11 -> 0 | E11: =SUM(B11:D11) -> 0 | F11: TB
A12: Plant Equip 15050 | B12: =+'FY 2019 2020'!E12 -> 2248968.1 | C12: =+'Plant Equip'!F71 -> 10785.81 | D12: =-2380-2392 -> -4772 | E12: =SUM(B12:D12) -> 2254981.9 | F12: TB
A13: Buildings | B13: =+'FY 2019 2020'!E13 -> 0 | E13: =SUM(B13:D13) -> 0
A14: Land | B14: =+'FY 2019 2020'!E14 -> 0 | E14: =SUM(B14:D14) -> 0
B15: =SUM(B8:B14) -> 2711116.5 | C15: =SUM(C8:C14) -> 20208.39 | D15: =SUM(D8:D14) -> -30554.91 | E15: =SUM(E8:E14) -> 2700770 | F15: Thomson Reuters
B17: Beg Balance | E17: End Balance
A18: Accum Depreciation | B18: 4/1/2020 | C18: Additions | D18: Disposals | E18: 44286
A20: Office Equip 15019 | B20: =+'FY 2019 2020'!E23 -> -251663.66 | C20: =23.39-946.03-638.87-946-638.85-992.77-638.86+46.78-946-638.85-946.04-638.86-946.01-638.86-945.96-638.86-966.5-638.85-966.47-638.85-960.86-638.86-141.35-1102.22-638.86-1102.24-621.81 -> -19487.52 | D20: =+'Disposal FY 2020 2021'!C18+'Disposal FY 2020 2021'!C25+'Disposal FY 2020 2021'!C32+'Disposal FY 2020 2021'!C39+'Disposal FY 2020 2021'!C63+'Disposal FY 2020 2021'!C76+'Disposal FY 2020 2021'!C105 -> 25782.91 | E20: =SUM(B20:D20) -> -245368.27 | F20: TB
A21: Furniture & Fixtures 15029 | B21: =+'FY 2019 2020'!E24 -> -91248.2 | C21: =-1254.41-1254.4-1254.39-1254.38-1254.43-1254.37-1254.35-1254.41-1254.41-1254.39-1254.39-1254.39 -> -15052.72 | E21: =SUM(B21:D21) -> -106300.92 | F21: TB
A22: Vehicles | B22: =+'FY 2019 2020'!E25 -> 0 | E22: =SUM(B22:D22) -> 0
A23: Tooling Rental Equip 15040 | B23: =+'FY 2019 2020'!E26 -> 0 | E23: =SUM(B23:D23) -> 0 | F23: TB
A24: Plant Equip 15059 | B24: =+'FY 2019 2020'!E27 -> -1830012.7 | C24: =-12123.55-12123.58-17.23-12140.79-12140.75-12140.79-12140.81-12140.75-12243.73-12243.76-12201.38-12206.85-11517.82 -> -145381.79 | D24: =2380+2392 -> 4772 | E24: =SUM(B24:D24) -> -1970622.5 | F24: TB
A25: Buildings 15069 | B25: =+'FY 2019 2020'!E28 -> 0 | E25: =SUM(B25:D25) -> 0
B26: =SUM(B20:B25) -> -2172924.5 | C26: =SUM(C20:C25) -> -179922.03 | D26: =SUM(D20:D25) -> 30554.91 | E26: =SUM(E20:E25) -> -2322291.6 | F26: TB
B28: =+B15+B26 -> 538192 | C28: =+C15+C26 -> -159713.64 | D28: =+D15+D26 -> 0 | E28: =+E15+E26 -> 378478.36 | F28: Thomson Reuters
A30: LH Improvements | B30: =+'FY 2019 2020'!E17 -> 41752.9 | C30: 0 | E30: =SUM(B30:D30) -> 41752.9 | F30: TB
A31: Amort LH Improvement 15089-00 | B31: =+'FY 2019 2020'!E33 -> -1971.31 | C31: =-179.21-179.21-179.21-179.21-179.21-179.21-179.21-179.21-179.21-179.21-179.21-179.21 -> -2150.52 | D31: 0 | E31: =SUM(B31:D31) -> -4121.83 | F31: TB | G31: 20 year; SL | H31: =(43009.36/20)/12 -> 179.20567 | I31: 76220-09
A33: Fixed Assets Net | B33: =+B15+B30+B26+B31 -> 577973.59 | C33: =+C15+C30+C26+C31 -> -161864.16 | D33: =+D15+D30+D26+D31 -> 0 | E33: =+E15+E30+E26+E31 -> 416109.43 | F33: TB
B34: PY
A38: PY = ok to FA report
A39: TB = ok to TB

Sheet Disposal FY 2020 2021
A1: ='FY 2024 2025'!$A$1 -> AA Inc
A2: FA Disposals
A3: FY 2020 2021
A5: 1. | B5: Asset #428 - April 2020 - disposed of Balestrieri computer due to COVID and maternity leave
C6: Blanche Consulting LLC BC-1154 2.21.2020 | G6: 841.98 | H6: original invoice
C7: Blanche Consulting LLC BC-1154C 4.27.2020 | G7: -841.98 | H7: generated CM
C8: Entry to reverse Feb and March depr | H8: JE #11903
B10: JE # 11903
B11: A/D | C11: 23.39 | E11: 15019-00
B12: Depr | D12: =+C11 -> 23.39 | E12: 76210-09
A15: 2. | B15: Asset #89 - May 2020 - disposed of HP 4250n LaserJet Printer s/n CNRXR62902
B17: JE # 11996
B18: A/D | C18: 1217.94 | E18: 15019-00
B19: Asset | D19: =+C18 -> 1217.94 | E19: 15010-00
A22: 3. | B22: Asset #133 - Jan 2021 - disposed of SAP009 Xerox Fax
B24: JE # 12617
B25: A/D | C25: 2639.6 | E25: 15019-00
B26: Asset | D26: =+C25 -> 2639.6 | E26: 15010-00
A29: 4. | B29: Asset #306 - Jan 2021 - disposed KLUS0044 Bauer 5SHBRY1
B31: JE # 12635
B32: A/D | C32: 1653.18 | E32: 15019-00
B33: Asset | D33: =+C32 -> 1653.18 | E33: 15010-00
A36: 5. | B36: Asset #109 - Feb 2021 - disposed Tooling KLUS0021 MXL1211MLL
B38: JE # 12637
B39: A/D | C39: 689.06 | E39: 15019-00
B40: Asset | D40: =+C39 -> 689.06 | E40: 15010-00
A43: 6. | B43: Asset #207 - Mar 2021 - disposed Small Tools 2001
B45: JE # 12737
B46: A/D | C46: 2380 | E46: 15059-00
B47: Asset | D47: =+C46 -> 2380 | E47: 15050-00
A50: 7. | B50: Asset #208 - Mar 2021 - disposed 2003 Assets
B52: JE # 12738
B53: A/D | C53: 2392 | E53: 15059-00
B54: Asset | D54: =+C53 -> 2392 | E54: 15050-00
A57: 8. | B57: FA review and clean up - Mar 2021 - disposed computers
B58: Asset #'s: | C58: 85 | D58: 184 | E58: 308 | F58: 165
C59: 120 | D59: 192 | E59: 309
C60: 162 | D60: 193 | E60: 311
B62: JE # 12749
B63: A/D | C63: =+D64 -> 15030.62 | E63: 15019-00
...

Sheet FY 2019 2020
A1: ='FY 2024 2025'!$A$1 -> AA Inc
A2: Fixed Assets
A3: FY 2019 / 2020
B5: Beg Balance | E5: End Balance
A6: Assets | B6: 43556 | C6: Additions | D6: Disposals | E6: 43921
A8: Office Equip 15010 | B8: 258764.63 | C8: =+'Office & Computer Equip'!F86 -> 39434.63 | D8: =-1565.78-1754.3-715.7 -> -4035.78 | E8: =SUM(B8:D8) -> 294163.48 | F8: TB
A9: Furniture & Fixtures 15020 | B9: 175507.49 | D9: -7522.53 | E9: =SUM(B9:D9) -> 167984.96 | F9: TB
A10: Vehicles | B10: 0 | E10: =SUM(B10:D10) -> 0
A11: Tooling Rental Equip | B11: 0 | E11: =SUM(B11:D11) -> 0 | F11: TB
A12: Plant Equip 15050 | B12: 2246394.6 | C12: =+'Plant Equip'!F65 -> 18303.32 | D12: =-2702.37-2702.37-2669.92-7655.21 -> -15729.87 | E12: =SUM(B12:D12) -> 2248968.1 | F12: TB
A13: Buildings | B13: 0 | E13: =SUM(B13:D13) -> 0
A14: Land | B14: 0 | E14: =SUM(B14:D14) -> 0
B15: =SUM(B8:B14) -> 2680666.8 | C15: =SUM(C8:C14) -> 57737.95 | D15: =SUM(D8:D14) -> -27288.18 | E15: =SUM(E8:E14) -> 2711116.5 | F15: Thomson Reuters
A17: LH Improvements | B17: 0 | C17: =43009.36-1256.46 -> 41752.9 | E17: =SUM(B17:D17) -> 41752.9 | F17: TB
B20: Beg Balance | E20: End Balance
A21: Accum Depreciation | B21: 4/1/2019 | C21: Additions | D21: Disposals | E21: 43921
A23: Office Equip 15019 | B23: -240736.36 | C23: =-960.21-120.91-960.19-120.89-960.2-120.91-890.11-120.9-1018.07-120.91-938.69-120.9-938.65-132.25-1027.52-132.26-1027.55-132.27-978.78-272.03-990.47-272.05-916.59-568.97 -> -13842.28 | D23: =1565.78+633.5+715.7 -> 2914.98 | E23: =SUM(B23:D23) -> -251663.66 | F23: TB
A24: Furniture & Fixtures 15029 | B24: -82878.88 | C24: =-1328.91-1328.89-1294.67-1294.67-1294.7-1294.65-1294.64-1294.68-1271.66-1271.64-1271.63-1254.4 -> -15495.14 | D24: 7125.82 | E24: =SUM(B24:D24) -> -91248.2 | F24: TB
A25: Vehicles | B25: 0 | E25: =SUM(B25:D25) -> 0
A26: Tooling Rental Equip 15040 | B26: 0 | E26: =SUM(B26:D26) -> 0 | F26: TB
A27: Plant Equip 15059 | B27: -1697875 | C27: =-13403.11-13403.07-12059.8-12059.72-12059.79-12059.75-66.24-12126.02-12126.01-12126.05-12125.95-12126.08-12125.97 -> -147867.56 | D27: =8074.66+7655.21 -> 15729.87 | E27: =SUM(B27:D27) -> -1830012.7 | F27: TB
A28: Buildings 15069 | B28: 0 | E28: =SUM(B28:D28) -> 0
B29: =SUM(B23:B28) -> -2021490.2 | C29: =SUM(C23:C28) -> -177204.98 | D29: =SUM(D23:D28) -> 25770.67 | E29: =SUM(E23:E28) -> -2172924.5 | F29: TB
B31: =+B15+B29 -> 659176.54 | C31: =+C15+C29 -> -119467.03 | D31: =+D15+D29 -> -1517.51 | E31: =+E15+E29 -> 538192 | F31: Thomson Reuters
A33: Amort LH Improvement 15089-00 | B33: 0 | C33: =-179.21-179.21-179.21-179.21-179.21-179.21-179.21-179.21-179.21-179.21-179.21 -> -1971.31 | D33: 0 | E33: =SUM(B33:D33) -> -1971.31 | F33: TB | G33: 20 year; SL | H33: =(43009.36/20)/12 -> 179.20567 | I33: 76220-09
A35: Fixed Assets Net | B35: =+B15+B17+B29+B33 -> 659176.54 | C35: =+C15+C17+C29+C33 -> -79685.44 | D35: =+D15+D17+D29+D33 -> -1517.51 | E35: =+E15+E17+E29+E33 -> 577973.59 | F35: TB
B36: PY
A40: PY = ok to FA report
A41: TB = ok to TB

Sheet Disposal FY 2019 2020
A1: ='FY 2024 2025'!$A$1 -> AA Inc
A2: FA Disposals
A3: FY 2019 2020
A5: 1. | B5: Aug 2019 - Disposed asset #350 KLUS0061 Criss HLNYX52 - rental car break-in
B7: JE # 11190
B8: A/D | C8: 1565.78 | E8: 15019-00
B9: Asset | D9: 1565.78 | E9: 15010-00
A12: 2. | B12: Dec 2019 - Disposed asset #409 KLUS0078 Berleth 1J40752 - rental car break-in
C13: Disposed in DEC 2019 instead of OCT 2019 in error
B14: JE # 11553
B15: A/D | C15: 633.5 | E15: 15019-00
B16: Loss | C16: =+D17-C15 -> 1120.8 | E16: 95500-07SG
B17: Asset | D17: 1754.3 | E17: 15010-00
A20: 3. | B20: Jan 2020 - Disposed of asset #'s 50, 52 and 66; Grinding Wheels per JB 1.17.2020
B22: JE # 11573
B23: A/D | C23: =2702.37+2702.37+2669.92 -> 8074.66 | E23: 15059-00
B24: Asset | D24: =2702.37+2702.37+2669.92 -> 8074.66 | E24: 15050-00
A27: 4. | B27: March 2020 Tooling -02 disposals as a result of dept review by Jaclyn Harris (Bauer)
C28: 31; 117; 34; 58; 60; 62; 68; 83;
B30: JE # 11740
B31: A/D | C31: =+D33+1672.93 -> 7125.82 | E31: 15029-00
B32: Loss | C32: =+D33+D34-C31 -> 396.71
B33: Asset 31 | D33: 5452.89 | E33: 15020-00
B34: Asset 117 | D34: 2069.64 | E34: 15020-00
B36: A/D | C36: =1009.7+836.14+1376+701+2669.92+1062.45 -> 7655.21 | E36: 15059-00
B37: Asset 34 | D37: 1009.7 | E37: 15050-00
B38: Asset 58 | D38: 836.14 | E38: 15050-00
B39: Asset 60 | D39: 1376 | E39: 15050-00
B40: Asset 62 | D40: 701 | E40: 15050-00
B41: Asset 68 | D41: 2669.92 | E41: 15050-00
B42: Asset 83 | D42: 1062.45 | E42: 15050-00
A44: 5. | B44: March 2020 - Disposed asset #149
B46: JE # 11739
B47: A/D | C47: 715.7 | E47: 15019-00
B48: Asset | D48: 715.7 | E48: 15010-00

Sheet FY 2018 2019
A1: ='FY 2024 2025'!$A$1 -> AA Inc
A2: Fixed Assets
A3: FY 2018 / 2019
B5: Beg Balance | E5: End Balance
A6: Assets | B6: 43191 | C6: Additions | D6: Disposals | E6: 43555
A8: Office Equip 15010 | B8: 238885.24 | C8: =+'Office & Computer Equip'!F77 -> 21166.39 | D8: -1287 | E8: =SUM(B8:D8) -> 258764.63 | F8: TB
A9: Furniture & Fixtures 15020 | B9: 170470.59 | C9: =+'F&F'!E35 -> 5036.9 | E9: =SUM(B9:D9) -> 175507.49 | F9: TB
A10: Vehicles | B10: 0 | E10: =SUM(B10:D10) -> 0
A11: Tooling Rental Equip | B11: =+'FY 2016 2017'!E11 -> 227943.2 | D11: =-53665.2-103700-27378-43200 -> -227943.2 | E11: =SUM(B11:D11) -> 0 | F11: TB
A12: Plant Equip 15050 | B12: 2131067.1 | C12: =+'Plant Equip'!F60 -> 126350.25 | D12: =-996.75-10026 -> -11022.75 | E12: =SUM(B12:D12) -> 2246394.6 | F12: TB
A13: Buildings | B13: =+'FY 2016 2017'!E13 -> 0 | E13: =SUM(B13:D13) -> 0
A14: Land | B14: =+'FY 2016 2017'!E14 -> 0 | E14: =SUM(B14:D14) -> 0
B15: =SUM(B8:B14) -> 2768366.2 | C15: =SUM(C8:C14) -> 152553.54 | D15: =SUM(D8:D14) -> -240252.95 | E15: =SUM(E8:E14) -> 2680666.8
B18: Beg Balance | E18: End Balance
A19: Accum Depreciation | B19: 4/1/2018 | C19: Additions | D19: Disposals | E19: 43555
A21: Office Equip 15019 | B21: -220809.39 | C21: =-668.85-1107.63-729.55-1107.59-756.18-1107.62-756.15-1107.61-756.14-922.79-976.75-922.78-937.06-922.76-937.04-922.78-1003.57-922.78-1003.53-922.77-1025.6-120.91-1025.63-120.9 -> -20784.97 | D21: 858 | E21: =SUM(B21:D21) -> -240736.36 | F21: TB
A22: Furniture & Fixtures 15029 | B22: -67181.11 | C22: =-1268.93-1268.95-1268.91-1314.19-1314.23-1323.2-1323.19-1323.24-1323.25-1323.22-1323.24-1323.22 -> -15697.77 | E22: =SUM(B22:D22) -> -82878.88 | F22: TB
A23: Vehicles | B23: 0 | E23: =SUM(B23:D23) -> 0
A24: Tooling Rental Equip 15040 | B24: -227943.2 | D24: 227943.2 | E24: =SUM(B24:D24) -> 0 | F24: TB
A25: Plant Equip 15059 | B25: -1550897.3 | C25: =-12090.98-12090.94-12168.35-12168.29-12084.78-12228.84-13365.76-13365.77-13365.83-13380.43-13380.56-13380.48 -> -153071.01 | D25: =996.75+5096.55 -> 6093.3 | E25: =SUM(B25:D25) -> -1697875 | F25: TB
A26: Buildings 15069 | B26: =+'FY 2016 2017'!E26 -> 0 | E26: =SUM(B26:D26) -> 0
B27: =SUM(B21:B26) -> -2066831 | C27: =SUM(C21:C26) -> -189553.75 | D27: =SUM(D21:D26) -> 234894.5 | E27: =SUM(E21:E26) -> -2021490.2
A29: Fixed Assets Net | B29: =+B15+B27 -> 701535.2 | C29: =+C15+C27 -> -37000.21 | D29: =+D15+D27 -> -5358.45 | E29: =+E15+E27 -> 659176.54 | F29: TB
B30: PY
A34: PY = ok to FA report
A35: TB = ok to TB

Sheet Disposal FY 2018 2019
A1: ='FY 2024 2025'!$A$1 -> AA Inc
A2: FA Disposals
A3: FY 2018 2019
A5: 1. | B5: May 2018 - Disposed asset #362 KLUS0067 Blovsky D089N72 | G5: RM
B7: JE # 9947 / 9961
B8: A/D | C8: 858 | E8: 15019-00
B9: Asset | D9: 1287 | E9: 15010-00
B10: Loss | C10: =+D9-C8 -> 429 | E10: 95500-04BG
A13: 2. | B13: July 2018 - Disposed asset #37 Electro-Chemical Marking Assembly | G13: HW/JB
B15: JE # 10143
B16: A/D | C16: 996.75 | E16: 15059-00
B17: Asset | D17: 996.75 | E17: 15050-00
A20: 3. | B20: July 2018 - Disposed 1.27.2017 asset #177 Arcon 12-7, 5" LII 33036; accounting notified in July 2018 | J20: HW/JB
B22: JE # 10148 | G22: AR | H22: 10280
B23: A/D | C23: 5096.55 | E23: 15059-00 | G23: FA | I23: 10026
B24: Asset | D24: 10026 | E24: 15050-00 | G24: A/D | H24: 5096.55
B25: Loss | C25: =+D24-C23 -> 4929.45 | E25: 95500-02 | G25: GAIN | I25: =+H22+H24-I23 -> 5350.55
H26: =SUM(H22:H25) -> 15376.55 | I26: =SUM(I22:I25) -> 15376.55
B27: invoice #0223152 1.27.17; prior FYE netted to loss | G27: Recorded as a sale to a customer in error
A30: 4. | B30: July 2018 - AAC project asset #30 230 cutter blades | F30: HW/JB
B32: JE # 10144
B33: A/D | C33: 53665.2 | E33: 15049-00
B34: Asset | D34: =+C33 -> 53665.2 | E34: 15040-00
A37: 5. | B37: July 2018 - AAC project asset #41 900 cutter blades | F37: HW/JB
B39: JE # 10145
B40: A/D | C40: 103700 | E40: 15049-00
B41: Asset | D41: =+C40 -> 103700 | E41: 15040-00
A44: 6. | B44: July 2018 - AAC project asset #45 150 cutter blades | F44: HW/JB
B46: JE # 10146
B47: A/D | C47: 27378 | E47: 15049-00
B48: Asset | D48: =+C47 -> 27378 | E48: 15040-00
A51: 7. | B51: July 2018 - AAC project asset #61 375 cutter blades | F51: HW/JB
B53: JE # 10147
B54: A/D | C54: 43200 | E54: 15049-00
B55: Asset | D55: =+C54 -> 43200 | E55: 15040-00

Sheet FY 2017 2018
A1: ='FY 2024 2025'!$A$1 -> AA Inc
A2: Fixed Assets
A3: FY 2017 / 2018
B5: Beg Balance | E5: End Balance
A6: Assets | B6: 42826 | C6: Additions | D6: Disposals | E6: 43190
A8: Office Equip 15010 | B8: =+'FY 2016 2017'!E8 -> 253287.53 | C8: =+'Office & Computer Equip'!F67 -> -545.18 | D8: =-13327.11-530 -> -13857.11 | E8: =SUM(B8:D8) -> 238885.24 | F8: TB
A9: Furniture & Fixtures 15020 | B9: =+'FY 2016 2017'!E9 -> 151564.58 | C9: =+'F&F'!E31 -> 25415.01 | D9: =-6509 -> -6509 | E9: =SUM(B9:D9) -> 170470.59 | F9: TB
A10: Vehicles | B10: =+'FY 2016 2017'!E10 -> 0 | E10: =SUM(B10:D10) -> 0
A11: Tooling Rental Equip | B11: =+'FY 2016 2017'!E11 -> 227943.2 | E11: =SUM(B11:D11) -> 227943.2 | F11: TB
A12: Plant Equip 15050 | B12: =+'FY 2016 2017'!E12 -> 2809365 | C12: =+'Plant Equip'!F50 -> 30213.63 | D12: =-751.53-13260-721847.87+27347.87 -> -708511.53 | E12: =SUM(B12:D12) -> 2131067.1 | F12: TB
A13: Buildings | B13: =+'FY 2016 2017'!E13 -> 0 | E13: =SUM(B13:D13) -> 0
A14: Land | B14: =+'FY 2016 2017'!E14 -> 0 | E14: =SUM(B14:D14) -> 0
B15: =SUM(B8:B14) -> 3442160.4 | C15: =SUM(C8:C14) -> 55083.46 | D15: =SUM(D8:D14) -> -728877.64 | E15: =SUM(E8:E14) -> 2768366.2
B18: Beg Balance | E18: End Balance
A19: Accum Depreciation | B19: 4/1/2017 | C19: Additions | D19: Disposals | E19: 43190
A21: Office Equip 15019 | B21: =+'FY 2016 2017'!E21 -> -209964.11 | C21: =-1308.16-1224.37-1126.72-1241.39-1037.23-1241.42-888.31-1241.4-888.28-1225.7-888.31-1225.69-791.97-1107.59-823.53-1107.62-770.07-1107.61-776.11-1107.61-689.23-1107.61-668.84-1107.62 -> -24702.39 | D21: =13327.11+530 -> 13857.11 | E21: =SUM(B21:D21) -> -220809.39 | F21: TB
A22: Furniture & Fixtures 15029 | B22: =+'FY 2016 2017'!E22 -> -58740.5 | C22: =-1135.73-1180.02-1263.34-1263.38-1263.38-1263.36-1263.32-1263.38-1263.39-1263.35-1263.36-1263.6 -> -14949.61 | D22: =6509 -> 6509 | E22: =SUM(B22:D22) -> -67181.11 | F22: TB
A23: Vehicles | B23: =+'FY 2016 2017'!E23 -> 0 | E23: =SUM(B23:D23) -> 0
A24: Tooling Rental Equip 15040 | B24: =+'FY 2016 2017'!E24 -> -227943.2 | E24: =SUM(B24:D24) -> -227943.2 | F24: TB
A25: Plant Equip 15059 | B25: =+'FY 2016 2017'!E25 -> -1570284.3 | C25: =-17773.28-17859.17-17852.96-17852.91-17852.93-17838.93-32.95-17859.62-12049.56-12049.64-12049.53-12114.5-12134.07 -> -185320.05 | D25: =231.72+13260+198508.17-7292.77 -> 204707.12 | E25: =SUM(B25:D25) -> -1550897.3 | F25: TB
A26: Buildings 15069 | B26: =+'FY 2016 2017'!E26 -> 0 | E26: =SUM(B26:D26) -> 0
B27: =SUM(B21:B26) -> -2066932.2 | C27: =SUM(C21:C26) -> -224972.05 | D27: =SUM(D21:D26) -> 225073.23 | E27: =SUM(E21:E26) -> -2066831
A29: Fixed Assets Net | B29: =+B15+B27 -> 1375228.2 | C29: =+C15+C27 -> -169888.59 | D29: =+D15+D27 -> -503804.41 | E29: =+E15+E27 -> 701535.2 | F29: TB
B30: PY
A34: PY = ok to FA report
A35: TB = ok to TB

Sheet Disposal FY 2017 2018
A1: ='FY 2024 2025'!$A$1 -> AA Inc
A2: FA Disposals
A3: FY 2017 2018
A5: 1. | B5: Disposed misc computers on 5/19/2017 | G5: Cost | H5: Depr
C6: Asset #9 Comp Wrkst INTP3600EB | G6: 3795.86 | H6: 3795.86
C7: Asset #35 KLUS0021 Tooling Area Computer | G7: 1425.7 | H7: 1425.7
C8: Asset #79 Acer Computer (EF) | G8: 848.64 | H8: 848.64
C9: Asset #87 Dell Laptop TG | G9: 2368.04 | H9: 2368.04
C10: Asset #88 Laptop (RP) | G10: 1531.81 | H10: 1531.81
C11: Asset #94 Laptop (RM) | G11: 1541.24 | H11: 1541.24
C12: Asset #95 Laptop (JK) | G12: 1815.82 | H12: 1815.82
G13: =SUM(G6:G12) -> 13327.11 | H13: =SUM(H6:H12) -> 13327.11
B16: JE #8848
B17: A/D | C17: 13327.11 | E17: 15019-00
B18: Asset | D18: =+C17 -> 13327.11 | E18: 15010-00
A22: 2. | B22: Disposed wash station on 5/25/17
C23: Asset #197 Washer-Tools s/n 10030566
B25: JE #8857
B26: A/D | C26: 231.72 | E26: 15059-00
B27: Loss on Disposal | C27: 519.81 | E27: 95500-02
B28: Asset | D28: 751.53 | E28: 15050-00
A31: 3. | B31: Disposed Hofler assets 7/25/17
C32: Asset #201 Tools
C33: Asset #202 Furniture
C34: Asset #203 Tools
C35: Asset #204 Furniture
C36: Asset #205 Laser Pritner
C37: Asset #206 Furniture
B39: JE #9020
B40: A/D | C40: =530 -> 530 | E40: 15019-00
B41: A/D | C41: =5199+1190+120 -> 6509 | E41: 15029-00
B42: A/D | C42: =3075+10185 -> 13260 | E42: 15059-00
B43: Asset | D43: 530 | E43: 15010-00
B44: Asset | D44: =5199+1190+120 -> 6509 | E44: 15020-00
B45: Asset | D45: =3075+10185 -> 13260 | E45: 15050-00
A48: 4. | B48: Disposed Viper 500K Delta Research 11/6/2017
B50: Asset #331
B51: JE # 9395
B52: A/D | C52: 198508.17 | E52: 15059-00
B53: Asset | D53: 721847.87 | E53: 15050-00
...

Sheet Apr to May reconcile
A1: ='FY 2024 2025'!$A$1 -> AA Inc
A2: April 2017 to May 2017 reconciliation after disposals and class changes
E4: Book Prior
C5: Asset # | D5: Book Cost | E5: Depr
A7: April bal | B7: Computer | D7: 124288.08 | E7: =103889.5 -> 103889.5
A8: April depr | B8: Computer | E8: =1308.16 -> 1308.16
A9: May adj | B9: Computer DISP | C9: 9 | D9: -3795.86 | E9: -3795.86
B10: Computer DISP | C10: 35 | D10: -1425.7 | E10: -1425.7
B11: Computer DISP | C11: 79 | D11: -848.64 | E11: -848.64
B12: Computer DISP | C12: 87 | D12: -2368.04 | E12: -2368.04
B13: Computer DISP | C13: 88 | D13: -1531.81 | E13: -1531.81
B14: Computer DISP | C14: 94 | D14: -1541.24 | E14: -1541.24
B15: Computer DISP | C15: 95 | D15: -1815.82 | E15: -1815.82 | F15: =SUM(E9:E15) -> -13327.11
B16: Computer RCL | C16: 89 | D16: -1217.94 | E16: -1217.94
B17: Computer RCL | C17: 126 | D17: -778.62 | E17: -778.62
B18: Computer RCL | C18: 135 | D18: -6407.16 | E18: -6407.16
B19: Computer RCL | C19: 136 | D19: -675 | E19: -675
B20: Computer RCL | C20: 139 | D20: -627.34 | E20: -627.34
B21: Computer RCL | C21: 154 | D21: -15792 | E21: -15792
B22: Computer RCL | C22: 174 | D22: -627.91 | E22: -627.91
B23: Computer RCL | C23: 205 | D23: -530 | E23: -530
B24: Computer RCL | C24: 357 | D24: -1022.86 | E24: -238.67
B25: Computer RCL | C25: 370 | D25: -829.2 | E25: -115.16
D26: =SUM(D7:D25) -> 82452.94 | E26: =SUM(E7:E25) -> 64860.75
A28: April bal | B28: F&F | D28: 157186.48 | E28: =58740.51 -> 58740.51
A29: April depr | B29: F&F | E29: 1135.73
A30: May adj | B30: F&F RCL | C30: 135 | D30: 6407.16 | E30: 6407.16
B31: F&F RCL | C31: 370 | D31: 829.2 | E31: 115.16
B32: F&F ADD | C32: 386 | D32: 2556.75 | E32: 0
D33: =SUM(D28:D32) -> 166979.59 | E33: =SUM(E28:E32) -> 66398.56
A35: April bal | B35: Office | D35: 133593.94 | E35: 106074.57
A36: April depr | B36: Office | E36: 1224.37
A37: May adj | B37: Office RCL | C37: 89 | D37: 1217.94 | E37: 1217.94
B38: Office RCL | C38: 126 | D38: 778.62 | E38: 778.62
B39: Office RCL | C39: 136 | D39: 675 | E39: 675
B40: Office RCL | C40: 139 | D40: 627.34 | E40: 627.34
B41: Office RCL | C41: 154 | D41: 15792 | E41: 15792
B42: Office RCL | C42: 174 | D42: 627.91 | E42: 627.91
B43: Office RCL | C43: 205 | D43: 530 | E43: 530
B44: Office RCL | C44: 357 | D44: 1022.86 | E44: 238.67
...

Sheet FY 2016 2017
A1: ='FY 2024 2025'!$A$1 -> AA Inc
A2: Fixed Assets
A3: FY 2016 / 2017
B5: Beg Balance | E5: End Balance
A6: Assets | B6: 42461 | C6: Additions | D6: Disposals | E6: 42825
A8: Office Equip | B8: 238615.96 | C8: =+'Office & Computer Equip'!F57 -> 18127.19 | D8: =-1710.7-1744.92 -> -3455.62 | E8: =SUM(B8:D8) -> 253287.53 | F8: TB
A9: Furniture & Fixtures | B9: 97296.61 | C9: =+'F&F'!E20 -> 54267.97 | E9: =SUM(B9:D9) -> 151564.58 | F9: TB
A10: Vehicles | B10: =+'FY 2014 2015'!E10 -> 0 | E10: =SUM(B10:D10) -> 0
A11: Tooling Rental Equip | B11: =+'FY 2014 2015'!E11 -> 227943.2 | E11: =SUM(B11:D11) -> 227943.2 | F11: TB
A12: Plant Equip | B12: 2809365 | E12: =SUM(B12:D12) -> 2809365 | F12: TB
A13: Buildings | B13: 0 | E13: =SUM(B13:D13) -> 0
A14: Land | B14: 0 | E14: =SUM(B14:D14) -> 0
B15: =SUM(B8:B14) -> 3373220.8 | C15: =SUM(C8:C14) -> 72395.16 | D15: =SUM(D8:D14) -> -3455.62 | E15: =SUM(E8:E14) -> 3442160.4
B18: Beg Balance | E18: End Balance
A19: Accum Depreciation | B19: 4/1/2016 | C19: Additions | D19: Disposals | E19: 42825
A21: Office Equip 15019 | B21: -180804.46 | C21: =-1297.98-1513.62-1280.35-1513.61-1316.05-1513.63-1449.34-1120.49-1518.74-1120.52-1518.76-1120.52-1518.76-1120.49-1518.75-1120.52-1426.6-1140.95-1426.59-1140.98-1378.57-1140.96-36.94-1251.18-1140.97 -> -31645.87 | D21: =1710.7+775.52 -> 2486.22 | E21: =SUM(B21:D21) -> -209964.11 | F21: TB
A22: Furniture & Fixtures 15029 | B22: -47024.52 | C22: =-622.11-177.88-799.99-972.93-988.45-988.47-11.87-1009.36-1009.33-1009.37-1009.38-1038.94-1038.95-1038.95 -> -11715.98 | E22: =SUM(B22:D22) -> -58740.5 | F22: TB
A23: Vehicles | B23: =+'FY 2014 2015'!E23 -> 0 | E23: =SUM(B23:D23) -> 0
A24: Tooling Rental Equip 15040 | B24: =+'FY 2014 2015'!E24 -> -227943.2 | E24: =SUM(B24:D24) -> -227943.2 | F24: TB
A25: Plant Equip 15059 | B25: -1351882 | C25: =-18200.27-18200.2-18200.26-18200.23-18200.24-18200.23-18200.25-18200.2-18200.29-18200.21-18200.26-18199.68 -> -218402.32 | E25: =SUM(B25:D25) -> -1570284.3 | F25: TB
A26: Buildings 15069 | B26: 0 | E26: =SUM(B26:D26) -> 0
B27: =SUM(B21:B26) -> -1807654.2 | C27: =SUM(C21:C26) -> -261764.17 | D27: =SUM(D21:D26) -> 2486.22 | E27: =SUM(E21:E26) -> -2066932.2
A29: Fixed Assets Net | B29: =+B15+B27 -> 1565566.6 | C29: =+C15+C27 -> -189369.01 | D29: =+D15+D27 -> -969.4 | E29: =+E15+E27 -> 1375228.2 | F29: TB
B30: PY
A34: PY = ok to FA report
A35: TB = ok to TB

Sheet Disposal FY 2016 2017
A1: ='FY 2024 2025'!$A$1 -> AA Inc
A2: FA Disposals
A3: FY 2016 2017
A5: 1. | B5: Asset #164 KLSUS0009 Sullivan 3V7GWW1 | E5: 42490
B7: JE #7648
B8: A/D | C8: 1710.7 | E8: 15019-00
B9: Asset | D9: 1710.7 | E9: 15010-00
A13: 2. | B13: Asset #321 KLSUS0055 Gray 81FRJ12 | E13: 42490
B15: JE #7660
B16: A/D | C16: 775.52 | E16: 15019-00
B17: Asset | D17: 1744.92 | E17: 15010-00
B18: Loss on disposal | C18: =+D17-C16 -> 969.4 | E18: 95500-07BG

Sheet FY 2015 2016
A1: ='FY 2024 2025'!$A$1 -> AA Inc
A2: Fixed Assets
A3: FY 2015 / 2016
B5: Beg Balance | E5: End Balance
A6: Assets | B6: 42095 | C6: Additions | D6: Disposals | E6: 42460
A8: Office Equip | B8: =+'FY 2014 2015'!E8 -> 214494.85 | C8: =+'Office & Computer Equip'!F46 -> 24121.11 | E8: =SUM(B8:D8) -> 238615.96 | F8: TB
A9: Furniture & Fixtures | B9: =+'FY 2014 2015'!E9 -> 94298.11 | C9: =+'F&F'!E12 -> 2998.5 | E9: =SUM(B9:D9) -> 97296.61 | F9: TB
A10: Vehicles | B10: =+'FY 2014 2015'!E10 -> 0 | E10: =SUM(B10:D10) -> 0 | F10: TB
A11: Tooling Rental Equip | B11: =+'FY 2014 2015'!E11 -> 227943.2 | E11: =SUM(B11:D11) -> 227943.2 | F11: TB
A12: Plant Equip | B12: =+'FY 2014 2015'!E12 -> 2593867.2 | C12: =+'Plant Equip'!F37 -> 215497.85 | E12: =SUM(B12:D12) -> 2809365 | F12: TB
A13: Buildings | B13: =+'FY 2014 2015'!E13 -> 82196 | C13: =+Buildings!E10 -> -82196 | E13: =SUM(B13:D13) -> 0 | F13: TB
A14: Land | B14: =+'FY 2014 2015'!E14 -> 128200 | C14: =+Land!E10 -> -128200 | E14: =SUM(B14:D14) -> 0 | F14: TB
B15: =SUM(B8:B14) -> 3340999.4 | C15: =SUM(C8:C14) -> 32221.46 | D15: =SUM(D8:D14) -> 0 | E15: =SUM(E8:E14) -> 3373220.8
B18: Beg Balance | E18: End Balance
A19: Accum Depreciation | B19: =+B6 -> 42095 | C19: Additions | D19: Disposals | E19: =+E6 -> 42460
A21: Office Equip 15019 | B21: =+'FY 2014 2015'!E21 -> -164456.85 | C21: =-2506.49-701.26-2316.32-701.27+555.53-2131.86-701.26-2131.86-701.25+13698.94-2110.19-886.11-2089.72-763.31+2822.43-1939.9-763.31-1953.89-763.32-1953.91-763.3-1326.48-1278.02-1184.21-1278.02-1201.23-1278.02 -> -16347.61 | E21: =SUM(B21:D21) -> -180804.46 | F21: TB
A22: Furniture & Fixtures 15029 | B22: =+'FY 2014 2015'!E22 -> -39670.57 | C22: =-613.56-609.57-609.55-609.56-609.58-609.55-609.53-609.58-609.57-621.19-621.21-621.5 -> -7353.95 | E22: =SUM(B22:D22) -> -47024.52 | F22: TB
A23: Vehicles | B23: =+'FY 2014 2015'!E23 -> 0 | E23: =SUM(B23:D23) -> 0 | F23: TB
A24: Tooling Rental Equip 15040 | B24: =+'FY 2014 2015'!E24 -> -227943.2 | E24: =SUM(B24:D24) -> -227943.2 | F24: TB
A25: Plant Equip 15059 | B25: =+'FY 2014 2015'!E25 -> -1135351.1 | C25: =-17131.93-17123.07-63.77-410.23-17704.51-18423.43-18420.44-18226.07-18216.53-61.01-18252.35-18242.09-18085.14-18085.25-18085.13 -> -216530.95 | E25: =SUM(B25:D25) -> -1351882 | F25: TB
A26: Buildings 15069 | B26: =+'FY 2014 2015'!E26 -> -5822.22 | C26: =-171.24-171.24-171.25-171.24-171.24+6678.43 -> 5822.22 | E26: =SUM(B26:D26) -> 0 | F26: TB
B27: =SUM(B21:B26) -> -1573243.9 | C27: =SUM(C21:C26) -> -234410.29 | D27: =SUM(D21:D26) -> 0 | E27: =SUM(E21:E26) -> -1807654.2
A29: Fixed Assets Net | B29: =+B15+B27 -> 1767755.4 | C29: =+C15+C27 -> -202188.83 | D29: =+D15+D27 -> 0 | E29: =+E15+E27 -> 1565566.6 | F29: TB
B30: PY
A34: PY = ok to FA report; off .10 PASS
A35: √ = ok to FA report; off .01 PASS
A36: TB = ok to TB

Sheet Disposal FY 2015 2016
A1: 3 disposals detailed below
A3: Asset #313/#335 Cisco Router
A4: 5.27.15
A5: Returned to credit memo received
A7: JE #6691
A8: A/D | B8: 555.53 | D8: 15019-00
A9: Asset | C9: 609.74 | D9: 15010-00
A10: Loss on disposal | B10: =+C9-B8 -> 54.21 | D10: 95500-09
A12: Cisco router was returned to
A13: Original invoice contained two line items: Router and Service
A14: issued credit memo for Router only.
A16: R2015-0094 | B16: 1612.41 | C16: router
A17: R2015-0094 | B17: 609.74 | C17: service
B18: =SUM(B16:B17) -> 2222.15
A19: G2016-50070 | B19: -1612.41 | C19: credit memo
B20: =SUM(B18:B19) -> 609.74 | C20: JE to get remainder off the books
A22: Per review with Rob Marion, the following assets were deemed as disposable:
A23: Disposed 8.31.15 fully depreciated
A24: Asset #4 KOTC Network 3Com port hub | D24: 506 | E24: √
A25: Asset #11 HP 1200N Laser Printer - Service | D25: 653.88 | E25: √
A26: Asset #71 HP Printer 2420d | D26: 700.7 | E26: √
A27: Asset #76 Dell Laptop LAT D510 | D27: 1956.17 | E27: √
A28: Asset #77 Acer Computer | D28: 1066.4 | E28: √
A29: Asset #78 Gateway M465-E SB Laptop (FI) | D29: 2697.11 | E29: √
A30: Asset #80 Computer Chris Eldred | D30: 1330.77 | E30: √
A31: Asset #90 Dell Laptop | D31: 1323.94 | E31: √
A32: Asset #91 AD Dell Laptop | D32: 1942.98 | E32: √
A33: Asset #97 Beate Laptop | D33: 1097 | E33: √
A35: Asset #86 Laptop Software | D35: 423.99 | E35: √
A37: JE #
A38: A/D | B38: =SUM(D24:D35) -> 13698.94 | D38: 15019-00
A39: Asset | C39: =+B38 -> 13698.94 | D39: 15010-00
A42: Asset #118 and Asset #124 1200 Woodland sale
A43: 8.31.15
A44: JE #6938
A45: Cash | B45: 10011-00 | C45: 277236.85 | E45: cash received
A46: A/D Buildings | B46: 15069-00 | C46: 6678.43 | E46: A/D
A47: Taxes & Fees - Real Prop | B47: 76128-09 | C47: 928.67 | E47: net debits/credits to seller
A48: Land | B48: 15070-00 | D48: 128200 | E48: land
A49: Buildings | B49: 15060-00 | D49: 82196 | E49: building
...

Sheet FY 2014 2015
A1: ='FY 2024 2025'!$A$1 -> AA Inc
A2: Fixed Assets
A3: FY 2014 / 2015
B5: Beg Balance | E5: End Balance
A6: Assets | B6: 41730 | C6: Additions | D6: Disposals | E6: 42094
A8: Office Equip | B8: 183783.31 | C8: =+'Office & Computer Equip'!F32 -> 30711.54 | E8: =SUM(B8:D8) -> 214494.85 | F8: TB
A9: Furniture & Fixtures | B9: 90096.77 | C9: =+'F&F'!E10 -> 4201.34 | E9: =SUM(B9:D9) -> 94298.11 | F9: TB
A10: Vehicles | B10: 0 | E10: =SUM(B10:D10) -> 0 | F10: TB
A11: Tooling Rental Equip | B11: 227943.2 | E11: =SUM(B11:D11) -> 227943.2 | F11: TB
A12: Plant Equip | B12: 1852488.4 | C12: =+'Plant Equip'!F20 -> 741378.75 | E12: =SUM(B12:D12) -> 2593867.2 | F12: TB
A13: Buildings | B13: 82196 | E13: =SUM(B13:D13) -> 82196 | F13: TB
A14: Land | B14: 128200 | E14: =SUM(B14:D14) -> 128200 | F14: TB
B15: =SUM(B8:B14) -> 2564707.7 | C15: =SUM(C8:C14) -> 776291.63 | D15: =SUM(D8:D14) -> 0 | E15: =SUM(E8:E14) -> 3340999.4
B18: Beg Balance | E18: End Balance
A19: Accum Depreciation | B19: @ 4/1/14 | C19: Additions | D19: Disposals | E19: =+E6 -> 42094
A21: Office Equip 15019 | B21: -124902 | C21: =-3068.87-3140.43-3333.35-2264.17-1092.75-2178.1-1092.76-2364.59-1193.98-2348.75-1153.74-2348.85-1153.74-2466.21-999.77-2466.35-845.2-9.53+628.58-2485.94-845.17-2485.99-845.19 -> -39554.85 | E21: =SUM(B21:D21) -> -164456.85 | F21: TB
A22: Furniture & Fixtures 15029 | B22: -31478.25 | C22: =-668.27-668.24-693.74-693.71-700.78-686.66-693.73-693.72-693.73-674.89-674.83-650.02 -> -8192.32 | E22: =SUM(B22:D22) -> -39670.57 | F22: TB
A23: Vehicles | B23: 0 | E23: =SUM(B23:D23) -> 0 | F23: TB
A24: Tooling Rental Equip 15040 | B24: -227943.2 | E24: =SUM(B24:D24) -> -227943.2 | F24: TB
A25: Plant Equip 15059 | B25: -941355.61 | C25: =-15089.2-14895.4-15120.7-15120.69-15128.11-15128.06-15212.31-15219.75-15219.77-15162.25-49.44-51.37-15305.51-6019.39-21501.41+227.9 -> -193995.46 | E25: =SUM(B25:D25) -> -1135351.1 | F25: TB
A26: Buildings 15069 | B26: -3767.32 | C26: =-171.24-171.24-171.25-171.24-171.24-171.24-171.24-171.24-171.25-171.24-171.24-171.24 -> -2054.9 | E26: =SUM(B26:D26) -> -5822.22 | F26: TB
B27: =SUM(B21:B26) -> -1329446.4 | C27: =SUM(C21:C26) -> -243797.53 | D27: =SUM(D21:D26) -> 0 | E27: =SUM(E21:E26) -> -1573243.9
A29: Fixed Assets Net | B29: =+B15+B27 -> 1235261.3 | C29: =+C15+C27 -> 532494.1 | D29: =+D15+D27 -> 0 | E29: =+E15+E27 -> 1767755.4 | F29: TB
B30: PY
A34: PY = ok to FA report; off .10 PASS
A35: √ = ok to FA report; off .01 PASS
A36: TB = ok to TB

Sheet Disposal FY 2014 2015
A1: Asset #185 Chris Kuhn's computer lost in flood
A3: 42005 | B3: Disposal
